Workbook
Name Slicer_AtriRiskCategory: #N/A
Name Slicer_Department: #N/A
Name Slicer_Gender1: #N/A
Name Slicer_JobLevel: #N/A
Name Slicer_JobRole: #N/A
Name Slicer_OverTime: #N/A

Sheet RawData
A1: Age | B1: Attrition | C1: BusinessTravel | D1: DailyRate | E1: Department | F1: DistanceFromHome | G1: Education | H1: EducationField | I1: EmployeeCount | J1: EmployeeNumber | K1: EnvironmentSatisfaction | L1: Gender | M1: HourlyRate | N1: JobInvolvement | O1: JobLevel | P1: JobRole | Q1: JobSatisfaction | R1: MaritalStatus | S1: MonthlyIncome | T1: MonthlyRate | U1: NumCompaniesWorked | V1: Over18 | W1: OverTime | X1: PercentSalaryHike | Y1: PerformanceRating | Z1: RelationshipSatisfaction | AA1: StandardHours | AB1: StockOptionLevel | AC1: TotalWorkingYears | AD1: TrainingTimesLastYear | AE1: WorkLifeBalance | AF1: YearsAtCompany | AG1: YearsInCurrentRole | AH1: YearsSinceLastPromotion | AI1: YearsWithCurrManager
A2: 41 | B2: Yes | C2: Travel_Rarely | D2: 1102 | E2: Sales | F2: 1 | G2: 2 | H2: Life Sciences | I2: 1 | J2: 1 | K2: 2 | L2: Female | M2: 94 | N2: 3 | O2: 2 | P2: Sales Executive | Q2: 4 | R2: Single | S2: 5993 | T2: 19479 | U2: 8 | V2: Y | W2: Yes | X2: 11 | Y2: 3 | Z2: 1 | AA2: 80 | AB2: 0 | AC2: 8 | AD2: 0 | AE2: 1 | AF2: 6 | AG2: 4 | AH2: 0 | AI2: 5
A3: 49 | B3: No | C3: Travel_Frequently | D3: 279 | E3: Research & Development | F3: 8 | G3: 1 | H3: Life Sciences | I3: 1 | J3: 2 | K3: 3 | L3: Male | M3: 61 | N3: 2 | O3: 2 | P3: Research Scientist | Q3: 2 | R3: Married | S3: 5130 | T3: 24907 | U3: 1 | V3: Y | W3: No | X3: 23 | Y3: 4 | Z3: 4 | AA3: 80 | AB3: 1 | AC3: 10 | AD3: 3 | AE3: 3 | AF3: 10 | AG3: 7 | AH3: 1 | AI3: 7
A4: 37 | B4: Yes | C4: Travel_Rarely | D4: 1373 | E4: Research & Development | F4: 2 | G4: 2 | H4: Other | I4: 1 | J4: 4 | K4: 4 | L4: Male | M4: 92 | N4: 2 | O4: 1 | P4: Laboratory Technician | Q4: 3 | R4: Single | S4: 2090 | T4: 2396 | U4: 6 | V4: Y | W4: Yes | X4: 15 | Y4: 3 | Z4: 2 | AA4: 80 | AB4: 0 | AC4: 7 | AD4: 3 | AE4: 3 | AF4: 0 | AG4: 0 | AH4: 0 | AI4: 0
A5: 33 | B5: No | C5: Travel_Frequently | D5: 1392 | E5: Research & Development | F5: 3 | G5: 4 | H5: Life Sciences | I5: 1 | J5: 5 | K5: 4 | L5: Female | M5: 56 | N5: 3 | O5: 1 | P5: Research Scientist | Q5: 3 | R5: Married | S5: 2909 | T5: 23159 | U5: 1 | V5: Y | W5: Yes | X5: 11 | Y5: 3 | Z5: 3 | AA5: 80 | AB5: 0 | AC5: 8 | AD5: 3 | AE5: 3 | AF5: 8 | AG5: 7 | AH5: 3 | AI5: 0
A6: 27 | B6: No | C6: Travel_Rarely | D6: 591 | E6: Research & Development | F6: 2 | G6: 1 | H6: Medical | I6: 1 | J6: 7 | K6: 1 | L6: Male | M6: 40 | N6: 3 | O6: 1 | P6: Laboratory Technician | Q6: 2 | R6: Married | S6: 3468 | T6: 16632 | U6: 9 | V6: Y | W6: No | X6: 12 | Y6: 3 | Z6: 4 | AA6: 80 | AB6: 1 | AC6: 6 | AD6: 3 | AE6: 3 | AF6: 2 | AG6: 2 | AH6: 2 | AI6: 2
A7: 32 | B7: No | C7: Travel_Frequently | D7: 1005 | E7: Research & Development | F7: 2 | G7: 2 | H7: Life Sciences | I7: 1 | J7: 8 | K7: 4 | L7: Male | M7: 79 | N7: 3 | O7: 1 | P7: Laboratory Technician | Q7: 4 | R7: Single | S7: 3068 | T7: 11864 | U7: 0 | V7: Y | W7: No | X7: 13 | Y7: 3 | Z7: 3 | AA7: 80 | AB7: 0 | AC7: 8 | AD7: 2 | AE7: 2 | AF7: 7 | AG7: 7 | AH7: 3 | AI7: 6
A8: 59 | B8: No | C8: Travel_Rarely | D8: 1324 | E8: Research & Development | F8: 3 | G8: 3 | H8: Medical | I8: 1 | J8: 10 | K8: 3 | L8: Female | M8: 81 | N8: 4 | O8: 1 | P8: Laboratory Technician | Q8: 1 | R8: Married | S8: 2670 | T8: 9964 | U8: 4 | V8: Y | W8: Yes | X8: 20 | Y8: 4 | Z8: 1 | AA8: 80 | AB8: 3 | AC8: 12 | AD8: 3 | AE8: 2 | AF8: 1 | AG8: 0 | AH8: 0 | AI8: 0
A9: 30 | B9: No | C9: Travel_Rarely | D9: 1358 | E9: Research & Development | F9: 24 | G9: 1 | H9: Life Sciences | I9: 1 | J9: 11 | K9: 4 | L9: Male | M9: 67 | N9: 3 | O9: 1 | P9: Laboratory Technician | Q9: 3 | R9: Divorced | S9: 2693 | T9: 13335 | U9: 1 | V9: Y | W9: No | X9: 22 | Y9: 4 | Z9: 2 | AA9: 80 | AB9: 1 | AC9: 1 | AD9: 2 | AE9: 3 | AF9: 1 | AG9: 0 | AH9: 0 | AI9: 0
A10: 38 | B10: No | C10: Travel_Frequently | D10: 216 | E10: Research & Development | F10: 23 | G10: 3 | H10: Life Sciences | I10: 1 | J10: 12 | K10: 4 | L10: Male | M10: 44 | N10: 2 | O10: 3 | P10: Manufacturing Director | Q10: 3 | R10: Single | S10: 9526 | T10: 8787 | U10: 0 | V10: Y | W10: No | X10: 21 | Y10: 4 | Z10: 2 | AA10: 80 | AB10: 0 | AC10: 10 | AD10: 2 | AE10: 3 | AF10: 9 | AG10: 7 | AH10: 1 | AI10: 8
A11: 36 | B11: No | C11: Travel_Rarely | D11: 1299 | E11: Research & Development | F11: 27 | G11: 3 | H11: Medical | I11: 1 | J11: 13 | K11: 3 | L11: Male | M11: 94 | N11: 3 | O11: 2 | P11: Healthcare Representative | Q11: 3 | R11: Married | S11: 5237 | T11: 16577 | U11: 6 | V11: Y | W11: No | X11: 13 | Y11: 3 | Z11: 2 | AA11: 80 | AB11: 2 | AC11: 17 | AD11: 3 | AE11: 2 | AF11: 7 | AG11: 7 | AH11: 7 | AI11: 7
A12: 35 | B12: No | C12: Travel_Rarely | D12: 809 | E12: Research & Development | F12: 16 | G12: 3 | H12: Medical | I12: 1 | J12: 14 | K12: 1 | L12: Male | M12: 84 | N12: 4 | O12: 1 | P12: Laboratory Technician | Q12: 2 | R12: Married | S12: 2426 | T12: 16479 | U12: 0 | V12: Y | W12: No | X12: 13 | Y12: 3 | Z12: 3 | AA12: 80 | AB12: 1 | AC12: 6 | AD12: 5 | AE12: 3 | AF12: 5 | AG12: 4 | AH12: 0 | AI12: 3
A13: 29 | B13: No | C13: Travel_Rarely | D13: 153 | E13: Research & Development | F13: 15 | G13: 2 | H13: Life Sciences | I13: 1 | J13: 15 | K13: 4 | L13: Female | M13: 49 | N13: 2 | O13: 2 | P13: Laboratory Technician | Q13: 3 | R13: Single | S13: 4193 | T13: 12682 | U13: 0 | V13: Y | W13: Yes | X13: 12 | Y13: 3 | Z13: 4 | AA13: 80 | AB13: 0 | AC13: 10 | AD13: 3 | AE13: 3 | AF13: 9 | AG13: 5 | AH13: 0 | AI13: 8
... A1471: 34 | B1471: No | C1471: Travel_Rarely | D1471: 628 | E1471: Research & Development | F1471: 8 | G1471: 3 | H1471: Medical | I1471: 1 | J1471: 2068 | K1471: 2 | L1471: Male | M1471: 82 | N1471: 4 | O1471: 2 | P1471: Laboratory Technician | Q1471: 3 | R1471: Married | S1471: 4404 | T1471: 10228 | U1471: 2 | V1471: Y | W1471: No | X1471: 12 | Y1471: 3 | Z1471: 1 | AA1471: 80 | AB1471: 0 | AC1471: 6 | AD1471: 3 | AE1471: 4 | AF1471: 4 | AG1471: 3 | AH1471: 1 | AI1471: 2

Sheet Project overview
B2: Project Title | C2: IBM HR Analytics Dashboard
C3: Employee Attrition, Burnout & Workforce Risk Analysis
B7: Project Objective | C7: This project analyzes IBM HR employee data to identify patterns related to attrition, burnout, compensation, promotion stagnation, and workforce risk. The dashboard was built in Microsoft Excel using advanced analytical and visualization techniques to support HR decision-making.
B11: Tools & Features Used
C12: • PivotTables & PivotCharts
C13: • Interactive slicers
C14: • XLOOKUP employee profile system
C15: • Conditional formatting & heatmaps
C16: • Risk scoring models
C17: • Burnout & attrition analysis
C18: • Excel tables and added analysis columns (risk flags, burnout score, salary bands)
C19: • Practice project on the public IBM HR Analytics dataset (1,470 fictional employees)
C20: • Dynamic KPI cards
C21: • Executive-style dashboard design
B23: Key Analytical Areas | C23: The dashboard focuses on: • Employee attrition risk • Burnout indicators • Promotion stagnation analysis • Compensation and salary insights • Workforce segmentation • Department-level HR trends
B26: Navigation Instructions | C26: Dashboard → main interactive analytics page KPI_Pivot, Attrition, Compensation&Pay and the other topic sheets → PivotTable analysis HR_Data → analysis dataset with the added columns KPIs_overview → headline KPIs Findings → written findings with the figures
B29: Key Insights | C29: Overtime: 30.5% attrition with overtime against 10.4% without
C30: Tenure: 34.9% attrition in the first two years, 8.1% after ten years
C31: Lower salary bands contain higher concentrations of attrition and risk
C32: Tested and not supported: time since last promotion (leavers 1.95 years, stayers 2.23) and department-level burnout do not explain attrition
B36: Prepared by: Kimia Mirkamali

Sheet Dashboard
C12: =KPI_Pivot!C5 -> 1470 | F12: =KPI_Pivot!N6 -> 0.16122449 | I12: =KPI_Pivot!G5 -> 314 | L12: =KPI_Pivot!J5 -> 0.38312925 | O12: =KPI_Pivot!Q5 -> 6502.9313 | R12: =KPI_Pivot!D11 -> 147 | U12: =KPI_Pivot!K11 -> 0.29482993 | X12: =KPI_Pivot!Q10 -> 260
C13: Total Employees | F13: Attrition Rate | I13: High Risk Employees | L13: Average Risk Score | O13: Average Monthly Income | U13: Burnout Score
R15: High Burnout Employees | X15: Employees with high Stagnation
F57: Department Risk Heatmap | K57: Average of MonthlyIncome | L57: Attrition | O57: Count of EmployeeNumber | P57: BurnoutLevel | T57: Count of EmployeeNumber | U57: StagnationLevel | Y57: Count of EmployeeNumber | Z57: SalaryBands
F58: Count of EmployeeCount | G58: AtriRiskCategory | K58: AtriRiskCategory | L58: No | M58: Yes | O58: Department | P58: High Burnout | Q58: Low Burnout | R58: Medium Burnout | T58: Department | U58: High Stagnation | V58: Low Stagnation | W58: Medium Stagnation | Y58: Department | Z58: High Salary | AA58: Low Salary | AB58: Medium Salary | AC58: Grand Total
F59: Department | G59: High Risk | H59: Low Risk | I59: Medium Risk | K59: High Risk | L59: 10504.576 | M59: 8388.8333 | O59: Human Resources | P59: 0.031746032 | Q59: 0.66666667 | R59: 0.3015873 | T59: Human Resources | U59: 8 | V59: 49 | W59: 6 | Y59: Human Resources | Z59: 16 | AA59: 32 | AB59: 15 | AC59: 63
F60: Human Resources | G60: 13 | H60: 13 | I60: 37 | K60: Low Risk | L60: 6878.0679 | M60: 5276 | O60: Research & Development | P60: 0.10613944 | Q60: 0.61186264 | R60: 0.28199792 | T60: Research & Development | U60: 160 | V60: 725 | W60: 76 | Y60: Research & Development | Z60: 230 | AA60: 431 | AB60: 300 | AC60: 961
F61: Research & Development | G61: 204 | H61: 253 | I61: 504 | K61: Medium Risk | L61: 5065.3612 | M61: 3886.1646 | O61: Sales | P61: 0.096412556 | Q61: 0.63004484 | R61: 0.2735426 | T61: Sales | U61: 92 | V61: 323 | W61: 31 | Y61: Sales | Z61: 135 | AA61: 79 | AB61: 232 | AC61: 446
F62: Sales | G62: 97 | H62: 139 | I62: 210 | K62: Grand Total | L62: 6832.7397 | M62: 4787.0928 | O62: Grand Total | P62: 0.1 | Q62: 0.61972789 | R62: 0.28027211 | Y62: Grand Total | Z62: 381 | AA62: 542 | AB62: 547 | AC62: 1470
G69: Employee Risk Profile
B70: Insight | G70: 1 | H70: Employee Number
B71: Key Burnout Insights: | G71: =_xlfn.XLOOKUP(G70,HR[EmployeeNumber],HR[Department]) -> Sales | H71: Department
B72: • Employees with overtime show higher burnout scores (overtime is one input of the score) | G72: =_xlfn.XLOOKUP(G70,HR[EmployeeNumber],HR[JobRole]) -> Sales Executive | H72: Job Role
B73: • Burnout score and attrition move together; the score is built from risk factors, so part of this is by design | G73: =_xlfn.XLOOKUP(G70,HR[EmployeeNumber],HR[MonthlyIncome]) -> 5993 | H73: Monthly Income
B74: • Burnout scores differ little between departments and do not explain why Sales and HR lose more people | G74: =_xlfn.XLOOKUP(G70,HR[EmployeeNumber],HR[AttritionRiskScore]) -> 0.7 | H74: Risk Score
G75: =_xlfn.XLOOKUP(G70,HR[EmployeeNumber],HR[AtriRiskCategory]) -> Medium Risk | H75: Risk Level
G76: =_xlfn.XLOOKUP(G70,HR[EmployeeNumber],HR[OverTime]) -> Yes | H76: OverTime
B77: Strategic HR Recommendations | G77: =_xlfn.XLOOKUP(G70,HR[EmployeeNumber],HR[JobSatisfaction]) -> 4 | H77: Job Satisfaction
B78: • Review overtime exposure: attrition is about three times higher with overtime in every department • Strengthen onboarding and early-tenure support (34.9% attrition in the first two years) • Review pay in the low salary band, where attrition is highest • Monitor employees with low job involvement, job satisfaction or work-life balance ratings | G78: =_xlfn.XLOOKUP(G70,HR[EmployeeNumber],HR[WorkLifeBalance]) -> 1 | H78: WorkLife Balance
G79: =_xlfn.XLOOKUP(G70,HR[EmployeeNumber],HR[YearsAtCompany]) -> 6 | H79: Years At Company
G80: =_xlfn.XLOOKUP(G70,HR[EmployeeNumber],HR[EnvironmentSatisfaction]) -> 2 | H80: Environmental Satisfaction
G81: =_xlfn.XLOOKUP(G70,HR[EmployeeNumber],HR[PerformanceRating]) -> 3 | H81: Performance Rating
G82: =_xlfn.XLOOKUP(G70,HR[EmployeeNumber],HR[TotalWorkingYears]) -> 8 | H82: Total Working Years
G83: =_xlfn.XLOOKUP(G70,HR[EmployeeNumber],HR[YearsInCurrentRole]) -> 4 | H83: Years in Current Role
G84: =_xlfn.XLOOKUP(G70,HR[EmployeeNumber],HR[YearsSinceLastPromotion]) -> 0 | H84: Years Since Last Promotion
C105: AtriRiskCategory
C106: High Risk | D106: Low Risk | E106: Medium Risk | F106: Grand Total
B107: Average of AttritionRiskScore | C107: 0.34936306 | D107: 0.17728395 | E107: 0.50825566 | F107: 0.38312925

Sheet KPI_Pivot
C4: Count of EmployeeNumber | F4: AtriRiskCategory | G4: Count of EmployeeNumber | J4: Average of AttritionRiskScore | M4: Attrition | N4: Count of EmployeeNumber | Q4: Average of MonthlyIncome
C5: 1470 | F5: High Risk | G5: 314 | J5: 0.38312925 | M5: No | N5: 0.83877551 | Q5: 6502.9313
F6: Low Risk | G6: 405 | M6: Yes | N6: 0.16122449
F7: Medium Risk | G7: 751 | M7: Grand Total | N7: 1
F8: Grand Total | G8: 1470
P9: StagnationLevel | Q9: Count of EmployeeNumber | S9: Count of EmployeeNumber | T9: Attrition
C10: BurnoutLevel | D10: Count of EmployeeNumber | F10: Count of EmployeeNumber | G10: Attrition | K10: Average of Burnout | M10: LowProFlag | N10: Count of EmployeeNumber | P10: High Stagnation | Q10: 260 | S10: StagnationLevel | T10: No | U10: Yes | V10: Grand Total
C11: High Burnout | D11: 147 | F11: BurnoutLevel | G11: No | H11: Yes | I11: Grand Total | K11: 0.29482993 | M11: 0 | N11: 1210 | P11: Low Stagnation | Q11: 1097 | S11: High Stagnation | T11: 0.85769231 | U11: 0.14230769 | V11: 1
C12: Low Burnout | D12: 911 | F12: High Burnout | G12: 0.068707483 | H12: 0.031292517 | I12: 0.1 | M12: 1 | N12: 260 | P12: Medium Stagnation | Q12: 113 | S12: Low Stagnation | T12: 0.83044667 | U12: 0.16955333 | V12: 1
C13: Medium Burnout | D13: 412 | F13: Low Burnout | G13: 0.56122449 | H13: 0.058503401 | I13: 0.61972789 | M13: Grand Total | N13: 1470 | P13: Grand Total | Q13: 1470 | S13: Medium Stagnation | T13: 0.87610619 | U13: 0.12389381 | V13: 1
C14: Grand Total | D14: 1470 | F14: Medium Burnout | G14: 0.20884354 | H14: 0.071428571 | I14: 0.28027211 | S14: Grand Total | T14: 0.83877551 | U14: 0.16122449 | V14: 1
F15: Grand Total | G15: 0.83877551 | H15: 0.16122449 | I15: 1
C17: Count of EmployeeNumber | D17: BurnoutLevel
C18: StagnationLevel | D18: High Burnout | E18: Low Burnout | F18: Medium Burnout | G18: Grand Total | J18: Count of EmployeeNumber | K18: Attrition | O18: SalaryBands | P18: Average of AttritionRiskScore | R18: JobRole | S18: Average of MonthlyIncome
C19: High Stagnation | D19: 0.15769231 | E19: 0.52692308 | F19: 0.31538462 | G19: 1 | J19: SalaryBands | K19: No | L19: Yes | M19: Grand Total | O19: High Salary | P19: 0.29396325 | R19: Healthcare Representative | S19: 7528.7634
C20: Low Stagnation | D20: 0.084776664 | E20: 0.63719234 | F20: 0.27803099 | G20: 1 | J20: High Salary | K20: 341 | L20: 40 | M20: 381 | O20: Low Salary | P20: 0.43238007 | R20: Human Resources | S20: 4235.75
C21: Medium Stagnation | D21: 0.11504425 | E21: 0.66371681 | F21: 0.22123894 | G21: 1 | J21: Low Salary | K21: 405 | L21: 137 | M21: 542 | O21: Medium Salary | P21: 0.3964351 | R21: Laboratory Technician | S21: 3237.1699
C22: Grand Total | D22: 0.1 | E22: 0.61972789 | F22: 0.28027211 | G22: 1 | J22: Medium Salary | K22: 487 | L22: 60 | M22: 547 | O22: Grand Total | P22: 0.38312925 | R22: Manager | S22: 17181.676
J23: Grand Total | K23: 1233 | L23: 237 | M23: 1470 | R23: Manufacturing Director | S23: 7295.1379
R24: Research Director | S24: 16033.55
R25: Research Scientist | S25: 3239.9726
R26: Sales Executive | S26: 6924.2791
R27: Sales Representative | S27: 2626
R28: Grand Total | S28: 6502.9313

Sheet HR
A1: Age | B1: Attrition | C1: BusinessTravel | D1: DailyRate | E1: Department | F1: DistanceFromHome | G1: Education | H1: EducationField | I1: EmployeeCount | J1: EmployeeNumber | K1: EnvironmentSatisfaction | L1: Gender | M1: HourlyRate | N1: JobInvolvement | O1: JobLevel | P1: JobRole | Q1: JobSatisfaction | R1: MaritalStatus | S1: MonthlyIncome | T1: MonthlyRate | U1: NumCompaniesWorked | V1: Over18 | W1: OverTime | X1: PercentSalaryHike | Y1: PerformanceRating | Z1: RelationshipSatisfaction | AA1: StandardHours | AB1: StockOptionLevel | AC1: TotalWorkingYears | AD1: TrainingTimesLastYear | AE1: WorkLifeBalance | AF1: YearsAtCompany | AG1: YearsInCurrentRole | AH1: YearsSinceLastPromotion | AI1: YearsWithCurrManager | AJ1: OverTimeFlag | AK1: LowJobSatisFlag | AL1: LowWLBFlag | AM1: LowSalaryFlag | AN1: LowEnviFlag | AO1: LowProFlag | AP1: AttritionRiskScore | AQ1: AtriRiskCategory | AR1: Burnout | AS1: BurnoutLevel | AT1: StagnationLevel | AU1: SalaryBands | AV1: Column13 | AW1: Column14 | AX1: Column15 | AY1: Column16 | AZ1: Column17 | BA1: Column18 | BB1: Column19 | BC1: Column20 | BD1: Column21 | BE1: Column22 | BF1: Column23 | BG1: Column24 | BH1: Column25 | BI1: Column26 | BJ1: Column27 | BK1: Column28 | BL1: Column29 | BM1: Column30 | BN1: Column31 | BO1: Column32 | BP1: Column33 | BQ1: Column34 | BR1: Column35 | BS1: Column36 | BT1: Column37 | BU1: Column38 | BV1: Column39 | BW1: Column40 | BX1: Column41 | BY1: Column42 | BZ1: Column43 | CA1: Column44 | CB1: Column45 | CC1: Column46 | CD1: Column47 | CE1: Column48 | CF1: Column49 | CG1: Column50 | CH1: Column51 | CI1: Column52 | CJ1: Column53 | CK1: Column54 | CL1: Column55 | CM1: Column56 | CN1: Column57 | CO1: Column58 | CP1: Column59 | CQ1: Column60 | CR1: Column61 | CS1: Column62 | CT1: Column63 | CU1: Column64 | CV1: Column65
A2: 41 | B2: Yes | C2: Travel_Rarely | D2: 1102 | E2: Sales | F2: 1 | G2: 2 | H2: Life Sciences | I2: 1 | J2: 1 | K2: 2 | L2: Female | M2: 94 | N2: 3 | O2: 2 | P2: Sales Executive | Q2: 4 | R2: Single | S2: 5993 | T2: 19479 | U2: 8 | V2: Y | W2: Yes | X2: 11 | Y2: 3 | Z2: 1 | AA2: 80 | AB2: 0 | AC2: 8 | AD2: 0 | AE2: 1 | AF2: 6 | AG2: 4 | AH2: 0 | AI2: 5 | AJ2: =IF(HR[[#This Row],[OverTime]]="Yes",1,0) -> 1 | AK2: =IF(HR[[#This Row],[JobSatisfaction]]<=2,1,0) -> 0 | AL2: =IF(HR[[#This Row],[WorkLifeBalance]]<=2,1,0) -> 1 | AM2: =IF(HR[[#This Row],[MonthlyIncome]]<AVERAGE(HR[MonthlyIncome]),1,0) -> 1 | AN2: =IF(HR[[#This Row],[EnvironmentSatisfaction]]<=2,1,0) -> 1 | AO2: =IF(HR[[#This Row],[YearsSinceLastPromotion]]>4,1,0) -> 0 | AP2: =(HR[[#This Row],[OverTimeFlag]]*1.5+HR[[#This Row],[LowJobSatisFlag]]*2.5+HR[[#This Row],[LowWLBFlag]]*2+HR[[#This Row],[LowSalaryFlag]]*1.5+HR[[#This Row],[LowEnviFlag]]*2+HR[[#This Row],[LowProFlag]]*0.5)/10 -> 0.7 | AQ2: =IF(A2>=_xlfn.PERCENTILE.INC($A$2:$A$1000,0.8),"High Risk", IF(HR[[#This Row],[AttritionRiskScore]]>=_xlfn.PERCENTILE.INC($AP$2:$AP$1000,0.5),"Medium Risk","Low Risk")) -> Medium Risk | AR2: =(HR[[#This Row],[OverTimeFlag]]*4+HR[[#This Row],[LowWLBFlag]]*3+HR[[#This Row],[LowJobSatisFlag]]*2+HR[[#This Row],[LowProFlag]]*1)/10 -> 0.7 | AS2: =IF(AR2>=0.7,"High Burnout",IF(AR2>=0.4,"Medium Burnout","Low Burnout")) -> High Burnout | AT2: =IF(HR[[#This Row],[YearsSinceLastPromotion]]>4,"High Stagnation", IF(HR[[#This Row],[YearsSinceLastPromotion]]>=3,"Medium Stagnation","Low Stagnation")) -> Low Stagnation | AU2: =IF(HR[[#This Row],[MonthlyIncome]]<4000,"Low Salary", IF(HR[[#This Row],[MonthlyIncome]]<8000,"Medium Salary","High Salary")) -> Medium Salary
A3: 49 | B3: No | C3: Travel_Frequently | D3: 279 | E3: Research & Development | F3: 8 | G3: 1 | H3: Life Sciences | I3: 1 | J3: 2 | K3: 3 | L3: Male | M3: 61 | N3: 2 | O3: 2 | P3: Research Scientist | Q3: 2 | R3: Married | S3: 5130 | T3: 24907 | U3: 1 | V3: Y | W3: No | X3: 23 | Y3: 4 | Z3: 4 | AA3: 80 | AB3: 1 | AC3: 10 | AD3: 3 | AE3: 3 | AF3: 10 | AG3: 7 | AH3: 1 | AI3: 7 | AJ3: =IF(HR[[#This Row],[OverTime]]="Yes",1,0) -> 0 | AK3: =IF(HR[[#This Row],[JobSatisfaction]]<=2,1,0) -> 1 | AL3: =IF(HR[[#This Row],[WorkLifeBalance]]<=2,1,0) -> 0 | AM3: =IF(HR[[#This Row],[MonthlyIncome]]<AVERAGE(HR[MonthlyIncome]),1,0) -> 1 | AN3: =IF(HR[[#This Row],[EnvironmentSatisfaction]]<=2,1,0) -> 0 | AO3: =IF(HR[[#This Row],[YearsSinceLastPromotion]]>4,1,0) -> 0 | AP3: =(HR[[#This Row],[OverTimeFlag]]*1.5+HR[[#This Row],[LowJobSatisFlag]]*2.5+HR[[#This Row],[LowWLBFlag]]*2+HR[[#This Row],[LowSalaryFlag]]*1.5+HR[[#This Row],[LowEnviFlag]]*2+HR[[#This Row],[LowProFlag]]*0.5)/10 -> 0.4 | AQ3: =IF(A3>=_xlfn.PERCENTILE.INC($A$2:$A$1000,0.8),"High Risk", IF(HR[[#This Row],[AttritionRiskScore]]>=_xlfn.PERCENTILE.INC($AP$2:$AP$1000,0.5),"Medium Risk","Low Risk")) -> High Risk | AR3: =(HR[[#This Row],[OverTimeFlag]]*4+HR[[#This Row],[LowWLBFlag]]*3+HR[[#This Row],[LowJobSatisFlag]]*2+HR[[#This Row],[LowProFlag]]*1)/10 -> 0.2 | AS3: =IF(AR3>=0.7,"High Burnout",IF(AR3>=0.4,"Medium Burnout","Low Burnout")) -> Low Burnout | AT3: =IF(HR[[#This Row],[YearsSinceLastPromotion]]>4,"High Stagnation", IF(HR[[#This Row],[YearsSinceLastPromotion]]>=3,"Medium Stagnation","Low Stagnation")) -> Low Stagnation | AU3: =IF(HR[[#This Row],[MonthlyIncome]]<4000,"Low Salary", IF(HR[[#This Row],[MonthlyIncome]]<8000,"Medium Salary","High Salary")) -> Medium Salary
A4: 37 | B4: Yes | C4: Travel_Rarely | D4: 1373 | E4: Research & Development | F4: 2 | G4: 2 | H4: Other | I4: 1 | J4: 4 | K4: 4 | L4: Male | M4: 92 | N4: 2 | O4: 1 | P4: Laboratory Technician | Q4: 3 | R4: Single | S4: 2090 | T4: 2396 | U4: 6 | V4: Y | W4: Yes | X4: 15 | Y4: 3 | Z4: 2 | AA4: 80 | AB4: 0 | AC4: 7 | AD4: 3 | AE4: 3 | AF4: 0 | AG4: 0 | AH4: 0 | AI4: 0 | AJ4: =IF(HR[[#This Row],[OverTime]]="Yes",1,0) -> 1 | AK4: =IF(HR[[#This Row],[JobSatisfaction]]<=2,1,0) -> 0 | AL4: =IF(HR[[#This Row],[WorkLifeBalance]]<=2,1,0) -> 0 | AM4: =IF(HR[[#This Row],[MonthlyIncome]]<AVERAGE(HR[MonthlyIncome]),1,0) -> 1 | AN4: =IF(HR[[#This Row],[EnvironmentSatisfaction]]<=2,1,0) -> 0 | AO4: =IF(HR[[#This Row],[YearsSinceLastPromotion]]>4,1,0) -> 0 | AP4: =(HR[[#This Row],[OverTimeFlag]]*1.5+HR[[#This Row],[LowJobSatisFlag]]*2.5+HR[[#This Row],[LowWLBFlag]]*2+HR[[#This Row],[LowSalaryFlag]]*1.5+HR[[#This Row],[LowEnviFlag]]*2+HR[[#This Row],[LowProFlag]]*0.5)/10 -> 0.3 | AQ4: =IF(A4>=_xlfn.PERCENTILE.INC($A$2:$A$1000,0.8),"High Risk", IF(HR[[#This Row],[AttritionRiskScore]]>=_xlfn.PERCENTILE.INC($AP$2:$AP$1000,0.5),"Medium Risk","Low Risk")) -> Low Risk | AR4: =(HR[[#This Row],[OverTimeFlag]]*4+HR[[#This Row],[LowWLBFlag]]*3+HR[[#This Row],[LowJobSatisFlag]]*2+HR[[#This Row],[LowProFlag]]*1)/10 -> 0.4 | AS4: =IF(AR4>=0.7,"High Burnout",IF(AR4>=0.4,"Medium Burnout","Low Burnout")) -> Medium Burnout | AT4: =IF(HR[[#This Row],[YearsSinceLastPromotion]]>4,"High Stagnation", IF(HR[[#This Row],[YearsSinceLastPromotion]]>=3,"Medium Stagnation","Low Stagnation")) -> Low Stagnation | AU4: =IF(HR[[#This Row],[MonthlyIncome]]<4000,"Low Salary", IF(HR[[#This Row],[MonthlyIncome]]<8000,"Medium Salary","High Salary")) -> Low Salary
A5: 33 | B5: No | C5: Travel_Frequently | D5: 1392 | E5: Research & Development | F5: 3 | G5: 4 | H5: Life Sciences | I5: 1 | J5: 5 | K5: 4 | L5: Female | M5: 56 | N5: 3 | O5: 1 | P5: Research Scientist | Q5: 3 | R5: Married | S5: 2909 | T5: 23159 | U5: 1 | V5: Y | W5: Yes | X5: 11 | Y5: 3 | Z5: 3 | AA5: 80 | AB5: 0 | AC5: 8 | AD5: 3 | AE5: 3 | AF5: 8 | AG5: 7 | AH5: 3 | AI5: 0 | AJ5: =IF(HR[[#This Row],[OverTime]]="Yes",1,0) -> 1 | AK5: =IF(HR[[#This Row],[JobSatisfaction]]<=2,1,0) -> 0 | AL5: =IF(HR[[#This Row],[WorkLifeBalance]]<=2,1,0) -> 0 | AM5: =IF(HR[[#This Row],[MonthlyIncome]]<AVERAGE(HR[MonthlyIncome]),1,0) -> 1 | AN5: =IF(HR[[#This Row],[EnvironmentSatisfaction]]<=2,1,0) -> 0 | AO5: =IF(HR[[#This Row],[YearsSinceLastPromotion]]>4,1,0) -> 0 | AP5: =(HR[[#This Row],[OverTimeFlag]]*1.5+HR[[#This Row],[LowJobSatisFlag]]*2.5+HR[[#This Row],[LowWLBFlag]]*2+HR[[#This Row],[LowSalaryFlag]]*1.5+HR[[#This Row],[LowEnviFlag]]*2+HR[[#This Row],[LowProFlag]]*0.5)/10 -> 0.3 | AQ5: =IF(A5>=_xlfn.PERCENTILE.INC($A$2:$A$1000,0.8),"High Risk", IF(HR[[#This Row],[AttritionRiskScore]]>=_xlfn.PERCENTILE.INC($AP$2:$AP$1000,0.5),"Medium Risk","Low Risk")) -> Low Risk | AR5: =(HR[[#This Row],[OverTimeFlag]]*4+HR[[#This Row],[LowWLBFlag]]*3+HR[[#This Row],[LowJobSatisFlag]]*2+HR[[#This Row],[LowProFlag]]*1)/10 -> 0.4 | AS5: =IF(AR5>=0.7,"High Burnout",IF(AR5>=0.4,"Medium Burnout","Low Burnout")) -> Medium Burnout | AT5: =IF(HR[[#This Row],[YearsSinceLastPromotion]]>4,"High Stagnation", IF(HR[[#This Row],[YearsSinceLastPromotion]]>=3,"Medium Stagnation","Low Stagnation")) -> Medium Stagnation | AU5: =IF(HR[[#This Row],[MonthlyIncome]]<4000,"Low Salary", IF(HR[[#This Row],[MonthlyIncome]]<8000,"Medium Salary","High Salary")) -> Low Salary
A6: 27 | B6: No | C6: Travel_Rarely | D6: 591 | E6: Research & Development | F6: 2 | G6: 1 | H6: Medical | I6: 1 | J6: 7 | K6: 1 | L6: Male | M6: 40 | N6: 3 | O6: 1 | P6: Laboratory Technician | Q6: 2 | R6: Married | S6: 3468 | T6: 16632 | U6: 9 | V6: Y | W6: No | X6: 12 | Y6: 3 | Z6: 4 | AA6: 80 | AB6: 1 | AC6: 6 | AD6: 3 | AE6: 3 | AF6: 2 | AG6: 2 | AH6: 2 | AI6: 2 | AJ6: =IF(HR[[#This Row],[OverTime]]="Yes",1,0) -> 0 | AK6: =IF(HR[[#This Row],[JobSatisfaction]]<=2,1,0) -> 1 | AL6: =IF(HR[[#This Row],[WorkLifeBalance]]<=2,1,0) -> 0 | AM6: =IF(HR[[#This Row],[MonthlyIncome]]<AVERAGE(HR[MonthlyIncome]),1,0) -> 1 | AN6: =IF(HR[[#This Row],[EnvironmentSatisfaction]]<=2,1,0) -> 1 | AO6: =IF(HR[[#This Row],[YearsSinceLastPromotion]]>4,1,0) -> 0 | AP6: =(HR[[#This Row],[OverTimeFlag]]*1.5+HR[[#This Row],[LowJobSatisFlag]]*2.5+HR[[#This Row],[LowWLBFlag]]*2+HR[[#This Row],[LowSalaryFlag]]*1.5+HR[[#This Row],[LowEnviFlag]]*2+HR[[#This Row],[LowProFlag]]*0.5)/10 -> 0.6 | AQ6: =IF(A6>=_xlfn.PERCENTILE.INC($A$2:$A$1000,0.8),"High Risk", IF(HR[[#This Row],[AttritionRiskScore]]>=_xlfn.PERCENTILE.INC($AP$2:$AP$1000,0.5),"Medium Risk","Low Risk")) -> Medium Risk | AR6: =(HR[[#This Row],[OverTimeFlag]]*4+HR[[#This Row],[LowWLBFlag]]*3+HR[[#This Row],[LowJobSatisFlag]]*2+HR[[#This Row],[LowProFlag]]*1)/10 -> 0.2 | AS6: =IF(AR6>=0.7,"High Burnout",IF(AR6>=0.4,"Medium Burnout","Low Burnout")) -> Low Burnout | AT6: =IF(HR[[#This Row],[YearsSinceLastPromotion]]>4,"High Stagnation", IF(HR[[#This Row],[YearsSinceLastPromotion]]>=3,"Medium Stagnation","Low Stagnation")) -> Low Stagnation | AU6: =IF(HR[[#This Row],[MonthlyIncome]]<4000,"Low Salary", IF(HR[[#This Row],[MonthlyIncome]]<8000,"Medium Salary","High Salary")) -> Low Salary
A7: 32 | B7: No | C7: Travel_Frequently | D7: 1005 | E7: Research & Development | F7: 2 | G7: 2 | H7: Life Sciences | I7: 1 | J7: 8 | K7: 4 | L7: Male | M7: 79 | N7: 3 | O7: 1 | P7: Laboratory Technician | Q7: 4 | R7: Single | S7: 3068 | T7: 11864 | U7: 0 | V7: Y | W7: No | X7: 13 | Y7: 3 | Z7: 3 | AA7: 80 | AB7: 0 | AC7: 8 | AD7: 2 | AE7: 2 | AF7: 7 | AG7: 7 | AH7: 3 | AI7: 6 | AJ7: =IF(HR[[#This Row],[OverTime]]="Yes",1,0) -> 0 | AK7: =IF(HR[[#This Row],[JobSatisfaction]]<=2,1,0) -> 0 | AL7: =IF(HR[[#This Row],[WorkLifeBalance]]<=2,1,0) -> 1 | AM7: =IF(HR[[#This Row],[MonthlyIncome]]<AVERAGE(HR[MonthlyIncome]),1,0) -> 1 | AN7: =IF(HR[[#This Row],[EnvironmentSatisfaction]]<=2,1,0) -> 0 | AO7: =IF(HR[[#This Row],[YearsSinceLastPromotion]]>4,1,0) -> 0 | AP7: =(HR[[#This Row],[OverTimeFlag]]*1.5+HR[[#This Row],[LowJobSatisFlag]]*2.5+HR[[#This Row],[LowWLBFlag]]*2+HR[[#This Row],[LowSalaryFlag]]*1.5+HR[[#This Row],[LowEnviFlag]]*2+HR[[#This Row],[LowProFlag]]*0.5)/10 -> 0.35 | AQ7: =IF(A7>=_xlfn.PERCENTILE.INC($A$2:$A$1000,0.8),"High Risk", IF(HR[[#This Row],[AttritionRiskScore]]>=_xlfn.PERCENTILE.INC($AP$2:$AP$1000,0.5),"Medium Risk","Low Risk")) -> Medium Risk | AR7: =(HR[[#This Row],[OverTimeFlag]]*4+HR[[#This Row],[LowWLBFlag]]*3+HR[[#This Row],[LowJobSatisFlag]]*2+HR[[#This Row],[LowProFlag]]*1)/10 -> 0.3 | AS7: =IF(AR7>=0.7,"High Burnout",IF(AR7>=0.4,"Medium Burnout","Low Burnout")) -> Low Burnout | AT7: =IF(HR[[#This Row],[YearsSinceLastPromotion]]>4,"High Stagnation", IF(HR[[#This Row],[YearsSinceLastPromotion]]>=3,"Medium Stagnation","Low Stagnation")) -> Medium Stagnation | AU7: =IF(HR[[#This Row],[MonthlyIncome]]<4000,"Low Salary", IF(HR[[#This Row],[MonthlyIncome]]<8000,"Medium Salary","High Salary")) -> Low Salary
A8: 59 | B8: No | C8: Travel_Rarely | D8: 1324 | E8: Research & Development | F8: 3 | G8: 3 | H8: Medical | I8: 1 | J8: 10 | K8: 3 | L8: Female | M8: 81 | N8: 4 | O8: 1 | P8: Laboratory Technician | Q8: 1 | R8: Married | S8: 2670 | T8: 9964 | U8: 4 | V8: Y | W8: Yes | X8: 20 | Y8: 4 | Z8: 1 | AA8: 80 | AB8: 3 | AC8: 12 | AD8: 3 | AE8: 2 | AF8: 1 | AG8: 0 | AH8: 0 | AI8: 0 | AJ8: =IF(HR[[#This Row],[OverTime]]="Yes",1,0) -> 1 | AK8: =IF(HR[[#This Row],[JobSatisfaction]]<=2,1,0) -> 1 | AL8: =IF(HR[[#This Row],[WorkLifeBalance]]<=2,1,0) -> 1 | AM8: =IF(HR[[#This Row],[MonthlyIncome]]<AVERAGE(HR[MonthlyIncome]),1,0) -> 1 | AN8: =IF(HR[[#This Row],[EnvironmentSatisfaction]]<=2,1,0) -> 0 | AO8: =IF(HR[[#This Row],[YearsSinceLastPromotion]]>4,1,0) -> 0 | AP8: =(HR[[#This Row],[OverTimeFlag]]*1.5+HR[[#This Row],[LowJobSatisFlag]]*2.5+HR[[#This Row],[LowWLBFlag]]*2+HR[[#This Row],[LowSalaryFlag]]*1.5+HR[[#This Row],[LowEnviFlag]]*2+HR[[#This Row],[LowProFlag]]*0.5)/10 -> 0.75 | AQ8: =IF(A8>=_xlfn.PERCENTILE.INC($A$2:$A$1000,0.8),"High Risk", IF(HR[[#This Row],[AttritionRiskScore]]>=_xlfn.PERCENTILE.INC($AP$2:$AP$1000,0.5),"Medium Risk","Low Risk")) -> High Risk | AR8: =(HR[[#This Row],[OverTimeFlag]]*4+HR[[#This Row],[LowWLBFlag]]*3+HR[[#This Row],[LowJobSatisFlag]]*2+HR[[#This Row],[LowProFlag]]*1)/10 -> 0.9 | AS8: =IF(AR8>=0.7,"High Burnout",IF(AR8>=0.4,"Medium Burnout","Low Burnout")) -> High Burnout | AT8: =IF(HR[[#This Row],[YearsSinceLastPromotion]]>4,"High Stagnation", IF(HR[[#This Row],[YearsSinceLastPromotion]]>=3,"Medium Stagnation","Low Stagnation")) -> Low Stagnation | AU8: =IF(HR[[#This Row],[MonthlyIncome]]<4000,"Low Salary", IF(HR[[#This Row],[MonthlyIncome]]<8000,"Medium Salary","High Salary")) -> Low Salary
A9: 30 | B9: No | C9: Travel_Rarely | D9: 1358 | E9: Research & Development | F9: 24 | G9: 1 | H9: Life Sciences | I9: 1 | J9: 11 | K9: 4 | L9: Male | M9: 67 | N9: 3 | O9: 1 | P9: Laboratory Technician | Q9: 3 | R9: Divorced | S9: 2693 | T9: 13335 | U9: 1 | V9: Y | W9: No | X9: 22 | Y9: 4 | Z9: 2 | AA9: 80 | AB9: 1 | AC9: 1 | AD9: 2 | AE9: 3 | AF9: 1 | AG9: 0 | AH9: 0 | AI9: 0 | AJ9: =IF(HR[[#This Row],[OverTime]]="Yes",1,0) -> 0 | AK9: =IF(HR[[#This Row],[JobSatisfaction]]<=2,1,0) -> 0 | AL9: =IF(HR[[#This Row],[WorkLifeBalance]]<=2,1,0) -> 0 | AM9: =IF(HR[[#This Row],[MonthlyIncome]]<AVERAGE(HR[MonthlyIncome]),1,0) -> 1 | AN9: =IF(HR[[#This Row],[EnvironmentSatisfaction]]<=2,1,0) -> 0 | AO9: =IF(HR[[#This Row],[YearsSinceLastPromotion]]>4,1,0) -> 0 | AP9: =(HR[[#This Row],[OverTimeFlag]]*1.5+HR[[#This Row],[LowJobSatisFlag]]*2.5+HR[[#This Row],[LowWLBFlag]]*2+HR[[#This Row],[LowSalaryFlag]]*1.5+HR[[#This Row],[LowEnviFlag]]*2+HR[[#This Row],[LowProFlag]]*0.5)/10 -> 0.15 | AQ9: =IF(A9>=_xlfn.PERCENTILE.INC($A$2:$A$1000,0.8),"High Risk", IF(HR[[#This Row],[AttritionRiskScore]]>=_xlfn.PERCENTILE.INC($AP$2:$AP$1000,0.5),"Medium Risk","Low Risk")) -> Low Risk | AR9: =(HR[[#This Row],[OverTimeFlag]]*4+HR[[#This Row],[LowWLBFlag]]*3+HR[[#This Row],[LowJobSatisFlag]]*2+HR[[#This Row],[LowProFlag]]*1)/10 -> 0 | AS9: =IF(AR9>=0.7,"High Burnout",IF(AR9>=0.4,"Medium Burnout","Low Burnout")) -> Low Burnout | AT9: =IF(HR[[#This Row],[YearsSinceLastPromotion]]>4,"High Stagnation", IF(HR[[#This Row],[YearsSinceLastPromotion]]>=3,"Medium Stagnation","Low Stagnation")) -> Low Stagnation | AU9: =IF(HR[[#This Row],[MonthlyIncome]]<4000,"Low Salary", IF(HR[[#This Row],[MonthlyIncome]]<8000,"Medium Salary","High Salary")) -> Low Salary
A10: 38 | B10: No | C10: Travel_Frequently | D10: 216 | E10: Research & Development | F10: 23 | G10: 3 | H10: Life Sciences | I10: 1 | J10: 12 | K10: 4 | L10: Male | M10: 44 | N10: 2 | O10: 3 | P10: Manufacturing Director | Q10: 3 | R10: Single | S10: 9526 | T10: 8787 | U10: 0 | V10: Y | W10: No | X10: 21 | Y10: 4 | Z10: 2 | AA10: 80 | AB10: 0 | AC10: 10 | AD10: 2 | AE10: 3 | AF10: 9 | AG10: 7 | AH10: 1 | AI10: 8 | AJ10: =IF(HR[[#This Row],[OverTime]]="Yes",1,0) -> 0 | AK10: =IF(HR[[#This Row],[JobSatisfaction]]<=2,1,0) -> 0 | AL10: =IF(HR[[#This Row],[WorkLifeBalance]]<=2,1,0) -> 0 | AM10: =IF(HR[[#This Row],[MonthlyIncome]]<AVERAGE(HR[MonthlyIncome]),1,0) -> 0 | AN10: =IF(HR[[#This Row],[EnvironmentSatisfaction]]<=2,1,0) -> 0 | AO10: =IF(HR[[#This Row],[YearsSinceLastPromotion]]>4,1,0) -> 0 | AP10: =(HR[[#This Row],[OverTimeFlag]]*1.5+HR[[#This Row],[LowJobSatisFlag]]*2.5+HR[[#This Row],[LowWLBFlag]]*2+HR[[#This Row],[LowSalaryFlag]]*1.5+HR[[#This Row],[LowEnviFlag]]*2+HR[[#This Row],[LowProFlag]]*0.5)/10 -> 0 | AQ10: =IF(A10>=_xlfn.PERCENTILE.INC($A$2:$A$1000,0.8),"High Risk", IF(HR[[#This Row],[AttritionRiskScore]]>=_xlfn.PERCENTILE.INC($AP$2:$AP$1000,0.5),"Medium Risk","Low Risk")) -> Low Risk | AR10: =(HR[[#This Row],[OverTimeFlag]]*4+HR[[#This Row],[LowWLBFlag]]*3+HR[[#This Row],[LowJobSatisFlag]]*2+HR[[#This Row],[LowProFlag]]*1)/10 -> 0 | AS10: =IF(AR10>=0.7,"High Burnout",IF(AR10>=0.4,"Medium Burnout","Low Burnout")) -> Low Burnout | AT10: =IF(HR[[#This Row],[YearsSinceLastPromotion]]>4,"High Stagnation", IF(HR[[#This Row],[YearsSinceLastPromotion]]>=3,"Medium Stagnation","Low Stagnation")) -> Low Stagnation | AU10: =IF(HR[[#This Row],[MonthlyIncome]]<4000,"Low Salary", IF(HR[[#This Row],[MonthlyIncome]]<8000,"Medium Salary","High Salary")) -> High Salary
A11: 36 | B11: No | C11: Travel_Rarely | D11: 1299 | E11: Research & Development | F11: 27 | G11: 3 | H11: Medical | I11: 1 | J11: 13 | K11: 3 | L11: Male | M11: 94 | N11: 3 | O11: 2 | P11: Healthcare Representative | Q11: 3 | R11: Married | S11: 5237 | T11: 16577 | U11: 6 | V11: Y | W11: No | X11: 13 | Y11: 3 | Z11: 2 | AA11: 80 | AB11: 2 | AC11: 17 | AD11: 3 | AE11: 2 | AF11: 7 | AG11: 7 | AH11: 7 | AI11: 7 | AJ11: =IF(HR[[#This Row],[OverTime]]="Yes",1,0) -> 0 | AK11: =IF(HR[[#This Row],[JobSatisfaction]]<=2,1,0) -> 0 | AL11: =IF(HR[[#This Row],[WorkLifeBalance]]<=2,1,0) -> 1 | AM11: =IF(HR[[#This Row],[MonthlyIncome]]<AVERAGE(HR[MonthlyIncome]),1,0) -> 1 | AN11: =IF(HR[[#This Row],[EnvironmentSatisfaction]]<=2,1,0) -> 0 | AO11: =IF(HR[[#This Row],[YearsSinceLastPromotion]]>4,1,0) -> 1 | AP11: =(HR[[#This Row],[OverTimeFlag]]*1.5+HR[[#This Row],[LowJobSatisFlag]]*2.5+HR[[#This Row],[LowWLBFlag]]*2+HR[[#This Row],[LowSalaryFlag]]*1.5+HR[[#This Row],[LowEnviFlag]]*2+HR[[#This Row],[LowProFlag]]*0.5)/10 -> 0.4 | AQ11: =IF(A11>=_xlfn.PERCENTILE.INC($A$2:$A$1000,0.8),"High Risk", IF(HR[[#This Row],[AttritionRiskScore]]>=_xlfn.PERCENTILE.INC($AP$2:$AP$1000,0.5),"Medium Risk","Low Risk")) -> Medium Risk | AR11: =(HR[[#This Row],[OverTimeFlag]]*4+HR[[#This Row],[LowWLBFlag]]*3+HR[[#This Row],[LowJobSatisFlag]]*2+HR[[#This Row],[LowProFlag]]*1)/10 -> 0.4 | AS11: =IF(AR11>=0.7,"High Burnout",IF(AR11>=0.4,"Medium Burnout","Low Burnout")) -> Medium Burnout | AT11: =IF(HR[[#This Row],[YearsSinceLastPromotion]]>4,"High Stagnation", IF(HR[[#This Row],[YearsSinceLastPromotion]]>=3,"Medium Stagnation","Low Stagnation")) -> High Stagnation | AU11: =IF(HR[[#This Row],[MonthlyIncome]]<4000,"Low Salary", IF(HR[[#This Row],[MonthlyIncome]]<8000,"Medium Salary","High Salary")) -> Medium Salary
A12: 35 | B12: No | C12: Travel_Rarely | D12: 809 | E12: Research & Development | F12: 16 | G12: 3 | H12: Medical | I12: 1 | J12: 14 | K12: 1 | L12: Male | M12: 84 | N12: 4 | O12: 1 | P12: Laboratory Technician | Q12: 2 | R12: Married | S12: 2426 | T12: 16479 | U12: 0 | V12: Y | W12: No | X12: 13 | Y12: 3 | Z12: 3 | AA12: 80 | AB12: 1 | AC12: 6 | AD12: 5 | AE12: 3 | AF12: 5 | AG12: 4 | AH12: 0 | AI12: 3 | AJ12: =IF(HR[[#This Row],[OverTime]]="Yes",1,0) -> 0 | AK12: =IF(HR[[#This Row],[JobSatisfaction]]<=2,1,0) -> 1 | AL12: =IF(HR[[#This Row],[WorkLifeBalance]]<=2,1,0) -> 0 | AM12: =IF(HR[[#This Row],[MonthlyIncome]]<AVERAGE(HR[MonthlyIncome]),1,0) -> 1 | AN12: =IF(HR[[#This Row],[EnvironmentSatisfaction]]<=2,1,0) -> 1 | AO12: =IF(HR[[#This Row],[YearsSinceLastPromotion]]>4,1,0) -> 0 | AP12: =(HR[[#This Row],[OverTimeFlag]]*1.5+HR[[#This Row],[LowJobSatisFlag]]*2.5+HR[[#This Row],[LowWLBFlag]]*2+HR[[#This Row],[LowSalaryFlag]]*1.5+HR[[#This Row],[LowEnviFlag]]*2+HR[[#This Row],[LowProFlag]]*0.5)/10 -> 0.6 | AQ12: =IF(A12>=_xlfn.PERCENTILE.INC($A$2:$A$1000,0.8),"High Risk", IF(HR[[#This Row],[AttritionRiskScore]]>=_xlfn.PERCENTILE.INC($AP$2:$AP$1000,0.5),"Medium Risk","Low Risk")) -> Medium Risk | AR12: =(HR[[#This Row],[OverTimeFlag]]*4+HR[[#This Row],[LowWLBFlag]]*3+HR[[#This Row],[LowJobSatisFlag]]*2+HR[[#This Row],[LowProFlag]]*1)/10 -> 0.2 | AS12: =IF(AR12>=0.7,"High Burnout",IF(AR12>=0.4,"Medium Burnout","Low Burnout")) -> Low Burnout | AT12: =IF(HR[[#This Row],[YearsSinceLastPromotion]]>4,"High Stagnation", IF(HR[[#This Row],[YearsSinceLastPromotion]]>=3,"Medium Stagnation","Low Stagnation")) -> Low Stagnation | AU12: =IF(HR[[#This Row],[MonthlyIncome]]<4000,"Low Salary", IF(HR[[#This Row],[MonthlyIncome]]<8000,"Medium Salary","High Salary")) -> Low Salary
A13: 29 | B13: No | C13: Travel_Rarely | D13: 153 | E13: Research & Development | F13: 15 | G13: 2 | H13: Life Sciences | I13: 1 | J13: 15 | K13: 4 | L13: Female | M13: 49 | N13: 2 | O13: 2 | P13: Laboratory Technician | Q13: 3 | R13: Single | S13: 4193 | T13: 12682 | U13: 0 | V13: Y | W13: Yes | X13: 12 | Y13: 3 | Z13: 4 | AA13: 80 | AB13: 0 | AC13: 10 | AD13: 3 | AE13: 3 | AF13: 9 | AG13: 5 | AH13: 0 | AI13: 8 | AJ13: =IF(HR[[#This Row],[OverTime]]="Yes",1,0) -> 1 | AK13: =IF(HR[[#This Row],[JobSatisfaction]]<=2,1,0) -> 0 | AL13: =IF(HR[[#This Row],[WorkLifeBalance]]<=2,1,0) -> 0 | AM13: =IF(HR[[#This Row],[MonthlyIncome]]<AVERAGE(HR[MonthlyIncome]),1,0) -> 1 | AN13: =IF(HR[[#This Row],[EnvironmentSatisfaction]]<=2,1,0) -> 0 | AO13: =IF(HR[[#This Row],[YearsSinceLastPromotion]]>4,1,0) -> 0 | AP13: =(HR[[#This Row],[OverTimeFlag]]*1.5+HR[[#This Row],[LowJobSatisFlag]]*2.5+HR[[#This Row],[LowWLBFlag]]*2+HR[[#This Row],[LowSalaryFlag]]*1.5+HR[[#This Row],[LowEnviFlag]]*2+HR[[#This Row],[LowProFlag]]*0.5)/10 -> 0.3 | AQ13: =IF(A13>=_xlfn.PERCENTILE.INC($A$2:$A$1000,0.8),"High Risk", IF(HR[[#This Row],[AttritionRiskScore]]>=_xlfn.PERCENTILE.INC($AP$2:$AP$1000,0.5),"Medium Risk","Low Risk")) -> Low Risk | AR13: =(HR[[#This Row],[OverTimeFlag]]*4+HR[[#This Row],[LowWLBFlag]]*3+HR[[#This Row],[LowJobSatisFlag]]*2+HR[[#This Row],[LowProFlag]]*1)/10 -> 0.4 | AS13: =IF(AR13>=0.7,"High Burnout",IF(AR13>=0.4,"Medium Burnout","Low Burnout")) -> Medium Burnout | AT13: =IF(HR[[#This Row],[YearsSinceLastPromotion]]>4,"High Stagnation", IF(HR[[#This Row],[YearsSinceLastPromotion]]>=3,"Medium Stagnation","Low Stagnation")) -> Low Stagnation | AU13: =IF(HR[[#This Row],[MonthlyIncome]]<4000,"Low Salary", IF(HR[[#This Row],[MonthlyIncome]]<8000,"Medium Salary","High Salary")) -> Medium Salary
... A1471: 34 | B1471: No | C1471: Travel_Rarely | D1471: 628 | E1471: Research & Development | F1471: 8 | G1471: 3 | H1471: Medical | I1471: 1 | J1471: 2068 | K1471: 2 | L1471: Male | M1471: 82 | N1471: 4 | O1471: 2 | P1471: Laboratory Technician | Q1471: 3 | R1471: Married | S1471: 4404 | T1471: 10228 | U1471: 2 | V1471: Y | W1471: No | X1471: 12 | Y1471: 3 | Z1471: 1 | AA1471: 80 | AB1471: 0 | AC1471: 6 | AD1471: 3 | AE1471: 4 | AF1471: 4 | AG1471: 3 | AH1471: 1 | AI1471: 2 | AJ1471: =IF(HR[[#This Row],[OverTime]]="Yes",1,0) -> 0 | AK1471: =IF(HR[[#This Row],[JobSatisfaction]]<=2,1,0) -> 0 | AL1471: =IF(HR[[#This Row],[WorkLifeBalance]]<=2,1,0) -> 0 | AM1471: =IF(HR[[#This Row],[MonthlyIncome]]<AVERAGE(HR[MonthlyIncome]),1,0) -> 1 | AN1471: =IF(HR[[#This Row],[EnvironmentSatisfaction]]<=2,1,0) -> 1 | AO1471: =IF(HR[[#This Row],[YearsSinceLastPromotion]]>4,1,0) -> 0 | AP1471: =(HR[[#This Row],[OverTimeFlag]]*1.5+HR[[#This Row],[LowJobSatisFlag]]*2.5+HR[[#This Row],[LowWLBFlag]]*2+HR[[#This Row],[LowSalaryFlag]]*1.5+HR[[#This Row],[LowEnviFlag]]*2+HR[[#This Row],[LowProFlag]]*0.5)/10 -> 0.35 | AQ1471: =IF(A1471>=_xlfn.PERCENTILE.INC($A$2:$A$1000,0.8),"High Risk", IF(HR[[#This Row],[AttritionRiskScore]]>=_xlfn.PERCENTILE.INC($AP$2:$AP$1000,0.5),"Medium Risk","Low Risk")) -> Medium Risk | AR1471: =(HR[[#This Row],[OverTimeFlag]]*4+HR[[#This Row],[LowWLBFlag]]*3+HR[[#This Row],[LowJobSatisFlag]]*2+HR[[#This Row],[LowProFlag]]*1)/10 -> 0 | AS1471: =IF(AR1471>=0.7,"High Burnout",IF(AR1471>=0.4,"Medium Burnout","Low Burnout")) -> Low Burnout | AT1471: =IF(HR[[#This Row],[YearsSinceLastPromotion]]>4,"High Stagnation", IF(HR[[#This Row],[YearsSinceLastPromotion]]>=3,"Medium Stagnation","Low Stagnation")) -> Low Stagnation | AU1471: =IF(HR[[#This Row],[MonthlyIncome]]<4000,"Low Salary", IF(HR[[#This Row],[MonthlyIncome]]<8000,"Medium Salary","High Salary")) -> Medium Salary

Sheet HR_Data
A1: Age | B1: AgeGroup | C1: Attrition | D1: AttritionRiskScore | E1: BurnoutScore | F1: BusinessTravel | G1: DailyRate | H1: Department | I1: DistanceFromHome | J1: EarlyLeaver | K1: Education | L1: EducationField | M1: EmployeeCount | N1: EmployeeNumber | O1: LowEnvironmentFlag | P1: EnvironmentSatisfaction | Q1: Gender | R1: HourlyRate | S1: JobInvolvement | T1: JobLevel | U1: JobRole | V1: JobSatisfaction | W1: MaritalStatus | X1: MonthlyIncome | Y1: RiskFlag | Z1: SalaryCategory | AA1: OvertimeFlag | AB1: LowSatisfactionFlag | AC1: LowWorkLifeBalanceFlag | AD1: LowSalaryFlag | AE1: MonthlyRate | AF1: NumCompaniesWorked | AG1: Over18 | AH1: OverTime | AI1: PercentSalaryHike | AJ1: PerformanceRating | AK1: RelationshipSatisfaction | AL1: RiskScore2 | AM1: RiskCategory | AN1: StandardHours | AO1: StockOptionLevel | AP1: TotalWorkingYears | AQ1: TrainingTimesLastYear | AR1: WorkLifeBalance | AS1: YearsAtCompany | AT1: YearsInCurrentRole | AU1: YearsSinceLastPromotion | AV1: YearsWithCurrManager | AW1: Column1
A2: 41 | B2: =IF(HR_Data[[#This Row],[Age]]<25,"<25", IF(HR_Data[[#This Row],[Age]]<35,"25–34", IF(HR_Data[[#This Row],[Age]]<45,"35–44", IF(HR_Data[[#This Row],[Age]]<55,"45–54","55+")))) -> 35–44 | C2: Yes | D2: =(HR[[#This Row],[OverTimeFlag]]*3+HR[[#This Row],[LowJobSatisFlag]]*5+HR[[#This Row],[LowWLBFlag]]*4+HR[[#This Row],[LowSalaryFlag]]*3+HR[[#This Row],[LowEnviFlag]]*4+HR[[#This Row],[LowProFlag]]*1) -> 14 | E2: =HR_Data[[#This Row],[OvertimeFlag]] + HR_Data[[#This Row],[LowSatisfactionFlag]] + HR_Data[[#This Row],[LowWorkLifeBalanceFlag]] -> 2 | F2: Travel_Rarely | G2: 1102 | H2: Sales | I2: 1 | J2: =IF(AND(HR_Data[[#This Row],[Attrition]]="Yes",HR_Data[[#This Row],[YearsAtCompany]]<2),"Yes","No") -> No | K2: 2 | L2: Life Sciences | M2: 1 | N2: 1 | P2: 2 | Q2: Female | R2: 94 | S2: 3 | T2: 2 | U2: Sales Executive | V2: 4 | W2: Single | X2: 5993 | Y2: =IF(AND(HR_Data[[#This Row],[OverTime]]="Yes",HR_Data[[#This Row],[JobSatisfaction]]<=2,HR_Data[[#This Row],[MonthlyIncome]]<AVERAGE(HR_Data[MonthlyIncome])), "High Risk", IF(OR(HR_Data[[#This Row],[OverTime]]="Yes",HR_Data[[#This Row],[JobSatisfaction]]<=2), "Medium Risk", "Low Risk")) -> Medium Risk | Z2: =IF(HR_Data[[#This Row],[MonthlyIncome]]<3000,"Low",IF(HR_Data[[#This Row],[MonthlyIncome]]<7000,"Medium","High")) -> Medium | AA2: =IF(HR_Data[[#This Row],[OverTime]]="Yes",1,0) -> 1 | AB2: =IF(HR_Data[[#This Row],[JobSatisfaction]]<=2,1,0) -> 0 | AC2: =IF(HR_Data[[#This Row],[WorkLifeBalance]]<=2,1,0) -> 1 | AD2: =IF(HR_Data[[#This Row],[MonthlyIncome]]<AVERAGE(HR_Data[MonthlyIncome]),1,0) -> 1 | AE2: 19479 | AF2: 8 | AG2: Y | AH2: Yes | AI2: 11 | AJ2: 3 | AK2: 1 | AL2: =IF(HR_Data[[#This Row],[OverTime]]="Yes",2,0) +IF(HR_Data[[#This Row],[WorkLifeBalance]]<=2,2,0) +IF(HR_Data[[#This Row],[MonthlyIncome]]<5000,2,0) +IF(HR_Data[[#This Row],[JobSatisfaction]]<=2,1,0) +IF(HR_Data[[#This Row],[EnvironmentSatisfaction]]<=2,1,0) +IF(HR_Data[[#This Row],[YearsAtCompany]]<2,2,0) -> 5 | AM2: =IF(HR_Data[[#This Row],[RiskScore2]]>=6,"High", IF(HR_Data[[#This Row],[RiskScore2]]>=3,"Medium","Low")) -> Medium | AN2: 80 | AO2: 0 | AP2: 8 | AQ2: 0 | AR2: 1 | AS2: 6 | AT2: 4 | AU2: 0 | AV2: 5
A3: 49 | B3: =IF(HR_Data[[#This Row],[Age]]<25,"<25", IF(HR_Data[[#This Row],[Age]]<35,"25–34", IF(HR_Data[[#This Row],[Age]]<45,"35–44", IF(HR_Data[[#This Row],[Age]]<55,"45–54","55+")))) -> 45–54 | C3: No | D3: =(HR[[#This Row],[OverTimeFlag]]*3+HR[[#This Row],[LowJobSatisFlag]]*5+HR[[#This Row],[LowWLBFlag]]*4+HR[[#This Row],[LowSalaryFlag]]*3+HR[[#This Row],[LowEnviFlag]]*4+HR[[#This Row],[LowProFlag]]*1) -> 8 | E3: =HR_Data[[#This Row],[OvertimeFlag]] + HR_Data[[#This Row],[LowSatisfactionFlag]] + HR_Data[[#This Row],[LowWorkLifeBalanceFlag]] -> 1 | F3: Travel_Frequently | G3: 279 | H3: Research & Development | I3: 8 | J3: =IF(AND(HR_Data[[#This Row],[Attrition]]="Yes",HR_Data[[#This Row],[YearsAtCompany]]<2),"Yes","No") -> No | K3: 1 | L3: Life Sciences | M3: 1 | N3: 2 | P3: 3 | Q3: Male | R3: 61 | S3: 2 | T3: 2 | U3: Research Scientist | V3: 2 | W3: Married | X3: 5130 | Y3: =IF(AND(HR_Data[[#This Row],[OverTime]]="Yes",HR_Data[[#This Row],[JobSatisfaction]]<=2,HR_Data[[#This Row],[MonthlyIncome]]<AVERAGE(HR_Data[MonthlyIncome])), "High Risk", IF(OR(HR_Data[[#This Row],[OverTime]]="Yes",HR_Data[[#This Row],[JobSatisfaction]]<=2), "Medium Risk", "Low Risk")) -> Medium Risk | Z3: =IF(HR_Data[[#This Row],[MonthlyIncome]]<3000,"Low",IF(HR_Data[[#This Row],[MonthlyIncome]]<7000,"Medium","High")) -> Medium | AA3: =IF(HR_Data[[#This Row],[OverTime]]="Yes",1,0) -> 0 | AB3: =IF(HR_Data[[#This Row],[JobSatisfaction]]<=2,1,0) -> 1 | AC3: =IF(HR_Data[[#This Row],[WorkLifeBalance]]<=2,1,0) -> 0 | AD3: =IF(HR_Data[[#This Row],[MonthlyIncome]]<AVERAGE(HR_Data[MonthlyIncome]),1,0) -> 1 | AE3: 24907 | AF3: 1 | AG3: Y | AH3: No | AI3: 23 | AJ3: 4 | AK3: 4 | AL3: =IF(HR_Data[[#This Row],[OverTime]]="Yes",2,0) +IF(HR_Data[[#This Row],[WorkLifeBalance]]<=2,2,0) +IF(HR_Data[[#This Row],[MonthlyIncome]]<5000,2,0) +IF(HR_Data[[#This Row],[JobSatisfaction]]<=2,1,0) +IF(HR_Data[[#This Row],[EnvironmentSatisfaction]]<=2,1,0) +IF(HR_Data[[#This Row],[YearsAtCompany]]<2,2,0) -> 1 | AM3: =IF(HR_Data[[#This Row],[RiskScore2]]>=6,"High", IF(HR_Data[[#This Row],[RiskScore2]]>=3,"Medium","Low")) -> Low | AN3: 80 | AO3: 1 | AP3: 10 | AQ3: 3 | AR3: 3 | AS3: 10 | AT3: 7 | AU3: 1 | AV3: 7
A4: 37 | B4: =IF(HR_Data[[#This Row],[Age]]<25,"<25", IF(HR_Data[[#This Row],[Age]]<35,"25–34", IF(HR_Data[[#This Row],[Age]]<45,"35–44", IF(HR_Data[[#This Row],[Age]]<55,"45–54","55+")))) -> 35–44 | C4: Yes | D4: =(HR[[#This Row],[OverTimeFlag]]*3+HR[[#This Row],[LowJobSatisFlag]]*5+HR[[#This Row],[LowWLBFlag]]*4+HR[[#This Row],[LowSalaryFlag]]*3+HR[[#This Row],[LowEnviFlag]]*4+HR[[#This Row],[LowProFlag]]*1) -> 6 | E4: =HR_Data[[#This Row],[OvertimeFlag]] + HR_Data[[#This Row],[LowSatisfactionFlag]] + HR_Data[[#This Row],[LowWorkLifeBalanceFlag]] -> 1 | F4: Travel_Rarely | G4: 1373 | H4: Research & Development | I4: 2 | J4: =IF(AND(HR_Data[[#This Row],[Attrition]]="Yes",HR_Data[[#This Row],[YearsAtCompany]]<2),"Yes","No") -> Yes | K4: 2 | L4: Other | M4: 1 | N4: 4 | P4: 4 | Q4: Male | R4: 92 | S4: 2 | T4: 1 | U4: Laboratory Technician | V4: 3 | W4: Single | X4: 2090 | Y4: =IF(AND(HR_Data[[#This Row],[OverTime]]="Yes",HR_Data[[#This Row],[JobSatisfaction]]<=2,HR_Data[[#This Row],[MonthlyIncome]]<AVERAGE(HR_Data[MonthlyIncome])), "High Risk", IF(OR(HR_Data[[#This Row],[OverTime]]="Yes",HR_Data[[#This Row],[JobSatisfaction]]<=2), "Medium Risk", "Low Risk")) -> Medium Risk | Z4: =IF(HR_Data[[#This Row],[MonthlyIncome]]<3000,"Low",IF(HR_Data[[#This Row],[MonthlyIncome]]<7000,"Medium","High")) -> Low | AA4: =IF(HR_Data[[#This Row],[OverTime]]="Yes",1,0) -> 1 | AB4: =IF(HR_Data[[#This Row],[JobSatisfaction]]<=2,1,0) -> 0 | AC4: =IF(HR_Data[[#This Row],[WorkLifeBalance]]<=2,1,0) -> 0 | AD4: =IF(HR_Data[[#This Row],[MonthlyIncome]]<AVERAGE(HR_Data[MonthlyIncome]),1,0) -> 1 | AE4: 2396 | AF4: 6 | AG4: Y | AH4: Yes | AI4: 15 | AJ4: 3 | AK4: 2 | AL4: =IF(HR_Data[[#This Row],[OverTime]]="Yes",2,0) +IF(HR_Data[[#This Row],[WorkLifeBalance]]<=2,2,0) +IF(HR_Data[[#This Row],[MonthlyIncome]]<5000,2,0) +IF(HR_Data[[#This Row],[JobSatisfaction]]<=2,1,0) +IF(HR_Data[[#This Row],[EnvironmentSatisfaction]]<=2,1,0) +IF(HR_Data[[#This Row],[YearsAtCompany]]<2,2,0) -> 6 | AM4: =IF(HR_Data[[#This Row],[RiskScore2]]>=6,"High", IF(HR_Data[[#This Row],[RiskScore2]]>=3,"Medium","Low")) -> High | AN4: 80 | AO4: 0 | AP4: 7 | AQ4: 3 | AR4: 3 | AS4: 0 | AT4: 0 | AU4: 0 | AV4: 0
A5: 33 | B5: =IF(HR_Data[[#This Row],[Age]]<25,"<25", IF(HR_Data[[#This Row],[Age]]<35,"25–34", IF(HR_Data[[#This Row],[Age]]<45,"35–44", IF(HR_Data[[#This Row],[Age]]<55,"45–54","55+")))) -> 25–34 | C5: No | D5: =(HR[[#This Row],[OverTimeFlag]]*3+HR[[#This Row],[LowJobSatisFlag]]*5+HR[[#This Row],[LowWLBFlag]]*4+HR[[#This Row],[LowSalaryFlag]]*3+HR[[#This Row],[LowEnviFlag]]*4+HR[[#This Row],[LowProFlag]]*1) -> 6 | E5: =HR_Data[[#This Row],[OvertimeFlag]] + HR_Data[[#This Row],[LowSatisfactionFlag]] + HR_Data[[#This Row],[LowWorkLifeBalanceFlag]] -> 1 | F5: Travel_Frequently | G5: 1392 | H5: Research & Development | I5: 3 | J5: =IF(AND(HR_Data[[#This Row],[Attrition]]="Yes",HR_Data[[#This Row],[YearsAtCompany]]<2),"Yes","No") -> No | K5: 4 | L5: Life Sciences | M5: 1 | N5: 5 | P5: 4 | Q5: Female | R5: 56 | S5: 3 | T5: 1 | U5: Research Scientist | V5: 3 | W5: Married | X5: 2909 | Y5: =IF(AND(HR_Data[[#This Row],[OverTime]]="Yes",HR_Data[[#This Row],[JobSatisfaction]]<=2,HR_Data[[#This Row],[MonthlyIncome]]<AVERAGE(HR_Data[MonthlyIncome])), "High Risk", IF(OR(HR_Data[[#This Row],[OverTime]]="Yes",HR_Data[[#This Row],[JobSatisfaction]]<=2), "Medium Risk", "Low Risk")) -> Medium Risk | Z5: =IF(HR_Data[[#This Row],[MonthlyIncome]]<3000,"Low",IF(HR_Data[[#This Row],[MonthlyIncome]]<7000,"Medium","High")) -> Low | AA5: =IF(HR_Data[[#This Row],[OverTime]]="Yes",1,0) -> 1 | AB5: =IF(HR_Data[[#This Row],[JobSatisfaction]]<=2,1,0) -> 0 | AC5: =IF(HR_Data[[#This Row],[WorkLifeBalance]]<=2,1,0) -> 0 | AD5: =IF(HR_Data[[#This Row],[MonthlyIncome]]<AVERAGE(HR_Data[MonthlyIncome]),1,0) -> 1 | AE5: 23159 | AF5: 1 | AG5: Y | AH5: Yes | AI5: 11 | AJ5: 3 | AK5: 3 | AL5: =IF(HR_Data[[#This Row],[OverTime]]="Yes",2,0) +IF(HR_Data[[#This Row],[WorkLifeBalance]]<=2,2,0) +IF(HR_Data[[#This Row],[MonthlyIncome]]<5000,2,0) +IF(HR_Data[[#This Row],[JobSatisfaction]]<=2,1,0) +IF(HR_Data[[#This Row],[EnvironmentSatisfaction]]<=2,1,0) +IF(HR_Data[[#This Row],[YearsAtCompany]]<2,2,0) -> 4 | AM5: =IF(HR_Data[[#This Row],[RiskScore2]]>=6,"High", IF(HR_Data[[#This Row],[RiskScore2]]>=3,"Medium","Low")) -> Medium | AN5: 80 | AO5: 0 | AP5: 8 | AQ5: 3 | AR5: 3 | AS5: 8 | AT5: 7 | AU5: 3 | AV5: 0
A6: 27 | B6: =IF(HR_Data[[#This Row],[Age]]<25,"<25", IF(HR_Data[[#This Row],[Age]]<35,"25–34", IF(HR_Data[[#This Row],[Age]]<45,"35–44", IF(HR_Data[[#This Row],[Age]]<55,"45–54","55+")))) -> 25–34 | C6: No | D6: =(HR[[#This Row],[OverTimeFlag]]*3+HR[[#This Row],[LowJobSatisFlag]]*5+HR[[#This Row],[LowWLBFlag]]*4+HR[[#This Row],[LowSalaryFlag]]*3+HR[[#This Row],[LowEnviFlag]]*4+HR[[#This Row],[LowProFlag]]*1) -> 12 | E6: =HR_Data[[#This Row],[OvertimeFlag]] + HR_Data[[#This Row],[LowSatisfactionFlag]] + HR_Data[[#This Row],[LowWorkLifeBalanceFlag]] -> 1 | F6: Travel_Rarely | G6: 591 | H6: Research & Development | I6: 2 | J6: =IF(AND(HR_Data[[#This Row],[Attrition]]="Yes",HR_Data[[#This Row],[YearsAtCompany]]<2),"Yes","No") -> No | K6: 1 | L6: Medical | M6: 1 | N6: 7 | P6: 1 | Q6: Male | R6: 40 | S6: 3 | T6: 1 | U6: Laboratory Technician | V6: 2 | W6: Married | X6: 3468 | Y6: =IF(AND(HR_Data[[#This Row],[OverTime]]="Yes",HR_Data[[#This Row],[JobSatisfaction]]<=2,HR_Data[[#This Row],[MonthlyIncome]]<AVERAGE(HR_Data[MonthlyIncome])), "High Risk", IF(OR(HR_Data[[#This Row],[OverTime]]="Yes",HR_Data[[#This Row],[JobSatisfaction]]<=2), "Medium Risk", "Low Risk")) -> Medium Risk | Z6: =IF(HR_Data[[#This Row],[MonthlyIncome]]<3000,"Low",IF(HR_Data[[#This Row],[MonthlyIncome]]<7000,"Medium","High")) -> Medium | AA6: =IF(HR_Data[[#This Row],[OverTime]]="Yes",1,0) -> 0 | AB6: =IF(HR_Data[[#This Row],[JobSatisfaction]]<=2,1,0) -> 1 | AC6: =IF(HR_Data[[#This Row],[WorkLifeBalance]]<=2,1,0) -> 0 | AD6: =IF(HR_Data[[#This Row],[MonthlyIncome]]<AVERAGE(HR_Data[MonthlyIncome]),1,0) -> 1 | AE6: 16632 | AF6: 9 | AG6: Y | AH6: No | AI6: 12 | AJ6: 3 | AK6: 4 | AL6: =IF(HR_Data[[#This Row],[OverTime]]="Yes",2,0) +IF(HR_Data[[#This Row],[WorkLifeBalance]]<=2,2,0) +IF(HR_Data[[#This Row],[MonthlyIncome]]<5000,2,0) +IF(HR_Data[[#This Row],[JobSatisfaction]]<=2,1,0) +IF(HR_Data[[#This Row],[EnvironmentSatisfaction]]<=2,1,0) +IF(HR_Data[[#This Row],[YearsAtCompany]]<2,2,0) -> 4 | AM6: =IF(HR_Data[[#This Row],[RiskScore2]]>=6,"High", IF(HR_Data[[#This Row],[RiskScore2]]>=3,"Medium","Low")) -> Medium | AN6: 80 | AO6: 1 | AP6: 6 | AQ6: 3 | AR6: 3 | AS6: 2 | AT6: 2 | AU6: 2 | AV6: 2
A7: 32 | B7: =IF(HR_Data[[#This Row],[Age]]<25,"<25", IF(HR_Data[[#This Row],[Age]]<35,"25–34", IF(HR_Data[[#This Row],[Age]]<45,"35–44", IF(HR_Data[[#This Row],[Age]]<55,"45–54","55+")))) -> 25–34 | C7: No | D7: =(HR[[#This Row],[OverTimeFlag]]*3+HR[[#This Row],[LowJobSatisFlag]]*5+HR[[#This Row],[LowWLBFlag]]*4+HR[[#This Row],[LowSalaryFlag]]*3+HR[[#This Row],[LowEnviFlag]]*4+HR[[#This Row],[LowProFlag]]*1) -> 7 | E7: =HR_Data[[#This Row],[OvertimeFlag]] + HR_Data[[#This Row],[LowSatisfactionFlag]] + HR_Data[[#This Row],[LowWorkLifeBalanceFlag]] -> 1 | F7: Travel_Frequently | G7: 1005 | H7: Research & Development | I7: 2 | J7: =IF(AND(HR_Data[[#This Row],[Attrition]]="Yes",HR_Data[[#This Row],[YearsAtCompany]]<2),"Yes","No") -> No | K7: 2 | L7: Life Sciences | M7: 1 | N7: 8 | P7: 4 | Q7: Male | R7: 79 | S7: 3 | T7: 1 | U7: Laboratory Technician | V7: 4 | W7: Single | X7: 3068 | Y7: =IF(AND(HR_Data[[#This Row],[OverTime]]="Yes",HR_Data[[#This Row],[JobSatisfaction]]<=2,HR_Data[[#This Row],[MonthlyIncome]]<AVERAGE(HR_Data[MonthlyIncome])), "High Risk", IF(OR(HR_Data[[#This Row],[OverTime]]="Yes",HR_Data[[#This Row],[JobSatisfaction]]<=2), "Medium Risk", "Low Risk")) -> Low Risk | Z7: =IF(HR_Data[[#This Row],[MonthlyIncome]]<3000,"Low",IF(HR_Data[[#This Row],[MonthlyIncome]]<7000,"Medium","High")) -> Medium | AA7: =IF(HR_Data[[#This Row],[OverTime]]="Yes",1,0) -> 0 | AB7: =IF(HR_Data[[#This Row],[JobSatisfaction]]<=2,1,0) -> 0 | AC7: =IF(HR_Data[[#This Row],[WorkLifeBalance]]<=2,1,0) -> 1 | AD7: =IF(HR_Data[[#This Row],[MonthlyIncome]]<AVERAGE(HR_Data[MonthlyIncome]),1,0) -> 1 | AE7: 11864 | AF7: 0 | AG7: Y | AH7: No | AI7: 13 | AJ7: 3 | AK7: 3 | AL7: =IF(HR_Data[[#This Row],[OverTime]]="Yes",2,0) +IF(HR_Data[[#This Row],[WorkLifeBalance]]<=2,2,0) +IF(HR_Data[[#This Row],[MonthlyIncome]]<5000,2,0) +IF(HR_Data[[#This Row],[JobSatisfaction]]<=2,1,0) +IF(HR_Data[[#This Row],[EnvironmentSatisfaction]]<=2,1,0) +IF(HR_Data[[#This Row],[YearsAtCompany]]<2,2,0) -> 4 | AM7: =IF(HR_Data[[#This Row],[RiskScore2]]>=6,"High", IF(HR_Data[[#This Row],[RiskScore2]]>=3,"Medium","Low")) -> Medium | AN7: 80 | AO7: 0 | AP7: 8 | AQ7: 2 | AR7: 2 | AS7: 7 | AT7: 7 | AU7: 3 | AV7: 6
A8: 59 | B8: =IF(HR_Data[[#This Row],[Age]]<25,"<25", IF(HR_Data[[#This Row],[Age]]<35,"25–34", IF(HR_Data[[#This Row],[Age]]<45,"35–44", IF(HR_Data[[#This Row],[Age]]<55,"45–54","55+")))) -> 55+ | C8: No | D8: =(HR[[#This Row],[OverTimeFlag]]*3+HR[[#This Row],[LowJobSatisFlag]]*5+HR[[#This Row],[LowWLBFlag]]*4+HR[[#This Row],[LowSalaryFlag]]*3+HR[[#This Row],[LowEnviFlag]]*4+HR[[#This Row],[LowProFlag]]*1) -> 15 | E8: =HR_Data[[#This Row],[OvertimeFlag]] + HR_Data[[#This Row],[LowSatisfactionFlag]] + HR_Data[[#This Row],[LowWorkLifeBalanceFlag]] -> 3 | F8: Travel_Rarely | G8: 1324 | H8: Research & Development | I8: 3 | J8: =IF(AND(HR_Data[[#This Row],[Attrition]]="Yes",HR_Data[[#This Row],[YearsAtCompany]]<2),"Yes","No") -> No | K8: 3 | L8: Medical | M8: 1 | N8: 10 | P8: 3 | Q8: Female | R8: 81 | S8: 4 | T8: 1 | U8: Laboratory Technician | V8: 1 | W8: Married | X8: 2670 | Y8: =IF(AND(HR_Data[[#This Row],[OverTime]]="Yes",HR_Data[[#This Row],[JobSatisfaction]]<=2,HR_Data[[#This Row],[MonthlyIncome]]<AVERAGE(HR_Data[MonthlyIncome])), "High Risk", IF(OR(HR_Data[[#This Row],[OverTime]]="Yes",HR_Data[[#This Row],[JobSatisfaction]]<=2), "Medium Risk", "Low Risk")) -> High Risk | Z8: =IF(HR_Data[[#This Row],[MonthlyIncome]]<3000,"Low",IF(HR_Data[[#This Row],[MonthlyIncome]]<7000,"Medium","High")) -> Low | AA8: =IF(HR_Data[[#This Row],[OverTime]]="Yes",1,0) -> 1 | AB8: =IF(HR_Data[[#This Row],[JobSatisfaction]]<=2,1,0) -> 1 | AC8: =IF(HR_Data[[#This Row],[WorkLifeBalance]]<=2,1,0) -> 1 | AD8: =IF(HR_Data[[#This Row],[MonthlyIncome]]<AVERAGE(HR_Data[MonthlyIncome]),1,0) -> 1 | AE8: 9964 | AF8: 4 | AG8: Y | AH8: Yes | AI8: 20 | AJ8: 4 | AK8: 1 | AL8: =IF(HR_Data[[#This Row],[OverTime]]="Yes",2,0) +IF(HR_Data[[#This Row],[WorkLifeBalance]]<=2,2,0) +IF(HR_Data[[#This Row],[MonthlyIncome]]<5000,2,0) +IF(HR_Data[[#This Row],[JobSatisfaction]]<=2,1,0) +IF(HR_Data[[#This Row],[EnvironmentSatisfaction]]<=2,1,0) +IF(HR_Data[[#This Row],[YearsAtCompany]]<2,2,0) -> 9 | AM8: =IF(HR_Data[[#This Row],[RiskScore2]]>=6,"High", IF(HR_Data[[#This Row],[RiskScore2]]>=3,"Medium","Low")) -> High | AN8: 80 | AO8: 3 | AP8: 12 | AQ8: 3 | AR8: 2 | AS8: 1 | AT8: 0 | AU8: 0 | AV8: 0
A9: 30 | B9: =IF(HR_Data[[#This Row],[Age]]<25,"<25", IF(HR_Data[[#This Row],[Age]]<35,"25–34", IF(HR_Data[[#This Row],[Age]]<45,"35–44", IF(HR_Data[[#This Row],[Age]]<55,"45–54","55+")))) -> 25–34 | C9: No | D9: =(HR[[#This Row],[OverTimeFlag]]*3+HR[[#This Row],[LowJobSatisFlag]]*5+HR[[#This Row],[LowWLBFlag]]*4+HR[[#This Row],[LowSalaryFlag]]*3+HR[[#This Row],[LowEnviFlag]]*4+HR[[#This Row],[LowProFlag]]*1) -> 3 | E9: =HR_Data[[#This Row],[OvertimeFlag]] + HR_Data[[#This Row],[LowSatisfactionFlag]] + HR_Data[[#This Row],[LowWorkLifeBalanceFlag]] -> 0 | F9: Travel_Rarely | G9: 1358 | H9: Research & Development | I9: 24 | J9: =IF(AND(HR_Data[[#This Row],[Attrition]]="Yes",HR_Data[[#This Row],[YearsAtCompany]]<2),"Yes","No") -> No | K9: 1 | L9: Life Sciences | M9: 1 | N9: 11 | P9: 4 | Q9: Male | R9: 67 | S9: 3 | T9: 1 | U9: Laboratory Technician | V9: 3 | W9: Divorced | X9: 2693 | Y9: =IF(AND(HR_Data[[#This Row],[OverTime]]="Yes",HR_Data[[#This Row],[JobSatisfaction]]<=2,HR_Data[[#This Row],[MonthlyIncome]]<AVERAGE(HR_Data[MonthlyIncome])), "High Risk", IF(OR(HR_Data[[#This Row],[OverTime]]="Yes",HR_Data[[#This Row],[JobSatisfaction]]<=2), "Medium Risk", "Low Risk")) -> Low Risk | Z9: =IF(HR_Data[[#This Row],[MonthlyIncome]]<3000,"Low",IF(HR_Data[[#This Row],[MonthlyIncome]]<7000,"Medium","High")) -> Low | AA9: =IF(HR_Data[[#This Row],[OverTime]]="Yes",1,0) -> 0 | AB9: =IF(HR_Data[[#This Row],[JobSatisfaction]]<=2,1,0) -> 0 | AC9: =IF(HR_Data[[#This Row],[WorkLifeBalance]]<=2,1,0) -> 0 | AD9: =IF(HR_Data[[#This Row],[MonthlyIncome]]<AVERAGE(HR_Data[MonthlyIncome]),1,0) -> 1 | AE9: 13335 | AF9: 1 | AG9: Y | AH9: No | AI9: 22 | AJ9: 4 | AK9: 2 | AL9: =IF(HR_Data[[#This Row],[OverTime]]="Yes",2,0) +IF(HR_Data[[#This Row],[WorkLifeBalance]]<=2,2,0) +IF(HR_Data[[#This Row],[MonthlyIncome]]<5000,2,0) +IF(HR_Data[[#This Row],[JobSatisfaction]]<=2,1,0) +IF(HR_Data[[#This Row],[EnvironmentSatisfaction]]<=2,1,0) +IF(HR_Data[[#This Row],[YearsAtCompany]]<2,2,0) -> 4 | AM9: =IF(HR_Data[[#This Row],[RiskScore2]]>=6,"High", IF(HR_Data[[#This Row],[RiskScore2]]>=3,"Medium","Low")) -> Medium | AN9: 80 | AO9: 1 | AP9: 1 | AQ9: 2 | AR9: 3 | AS9: 1 | AT9: 0 | AU9: 0 | AV9: 0
